<robot name="hoverpibot" xmlns:xacro="http://ros.org/wiki/xacro">

  <xacro:property name="robotwidth" value="0.60" />
  <xacro:property name="bodywidth" value="0.48" />
  <xacro:property name="bodylen" value="0.19" />
  <xacro:property name="bodyheight" value="0.10" />
  <xacro:property name="wheeldiam" value="0.1651" />
  <xacro:property name="wheelwidth" value="0.06" />
  <xacro:property name="pi" value="3.1415" />

  <material name="blue">
    <color rgba="0 0 0.8 1"/>
  </material>

  <material name="black">
    <color rgba="0 0 0 1"/>
  </material>

  <material name="white">
    <color rgba="1 1 1 1"/>
  </material>

  <xacro:macro name="default_inertial" params="mass">
    <inertial>
      <mass value="${mass}" />
      <inertia ixx="1.0" ixy="0.0" ixz="0.0" iyy="1.0" iyz="0.0" izz="1.0" />
    </inertial>
  </xacro:macro>


  <link name="base_link">
    <visual>
      <origin xyz="0 0 ${wheeldiam/2}" rpy="0 0 0" />
      <geometry>
        <box size="${bodylen} ${bodywidth} ${bodyheight}"/>
      </geometry>
      <material name="blue"/>
    </visual>
    <collision>
      <geometry>
        <box size="${bodylen} ${bodywidth} ${bodyheight}"/>
      </geometry>
    </collision>
    <xacro:default_inertial mass="10"/>
  </link>

  <link name="left_wheel">
    <visual>
      <origin xyz="0 -${bodywidth/2 + wheelwidth/2} 0" rpy="${pi/2} 0 0" />
      <geometry>
        <cylinder radius="${wheeldiam/2}" length="${wheelwidth}"/>
      </geometry>
      <material name="white"/>
    </visual>
    <collision>
      <geometry>
        <cylinder radius="${wheeldiam/2}" length="${wheelwidth}"/>
      </geometry>
    </collision>
    <xacro:default_inertial mass="1"/>
  </link>

  <joint name="left_wheel_joint" type="continuous">
    <axis xyz="0 1 0" />
    <parent link="base_link"/>
    <child link="left_wheel"/>
    <origin xyz="0 0 ${wheeldiam/2}" rpy="0 0 0"/>
  </joint>

  <link name="right_wheel">
    <visual>
      <origin xyz="0 ${bodywidth/2 + wheelwidth/2} 0" rpy="${pi/2} 0 0" />
      <geometry>
        <cylinder radius="${wheeldiam/2}" length="${wheelwidth}"/>
      </geometry>
      <material name="white"/>
    </visual>
    <collision>
      <geometry>
        <cylinder radius="${wheeldiam/2}" length="${wheelwidth}"/>
      </geometry>
    </collision>
    <xacro:default_inertial mass="1"/>
  </link>

  <joint name="right_wheel_joint" type="continuous">
    <axis xyz="0 1 0" />
    <parent link="base_link"/>
    <child link="right_wheel"/>
    <origin xyz="0 0 ${wheeldiam/2}" rpy="0 0 0"/>
  </joint>


  <!-- This block provides the simulator (Gazebo) with information on a few additional -
  physical properties. See http://gazebosim.org/tutorials/?tut=ros_urdf for more-->
  <gazebo reference="left_wheel">
    <mu1 value="200.0"/>
    <mu2 value="100.0"/>
    <kp value="10000000.0" />
    <kd value="1.0" />
    <material>Gazebo/Grey</material>
  </gazebo>

  <!-- This block connects the wheel joint to an actuator (motor), which informs both
  simulation and visualization of the robot -->

  <transmission name="left_wheel_trans">
    <type>transmission_interface/SimpleTransmission</type>
    <actuator name="left_wheel_motor">
      <mechanicalReduction>1</mechanicalReduction>
    </actuator>
    <joint name="left_wheel_joint">
      <hardwareInterface>hardware_interface/VelocityJointInterface</hardwareInterface>
    </joint>
  </transmission>

  <transmission name="right_wheel_trans">
    <type>transmission_interface/SimpleTransmission</type>
    <actuator name="right_wheel_motor">
      <mechanicalReduction>1</mechanicalReduction>
    </actuator>
    <joint name="right_wheel_joint">
      <hardwareInterface>hardware_interface/VelocityJointInterface</hardwareInterface>
    </joint>
  </transmission>

  <!-- Gazebo plugin for ROS Control -->
  <gazebo>
    <plugin name="gazebo_ros_control" filename="libgazebo_ros_control.so">
      <robotNamespace>/</robotNamespace>
    </plugin>
  </gazebo>
